[2024-11-22T06:39:04.147+0000] {local_task_job_runner.py:123} INFO - ::group::Pre task execution logs
[2024-11-22T06:39:04.234+0000] {taskinstance.py:2613} INFO - Dependencies all met for dep_context=non-requeueable deps ti=<TaskInstance: university_ranking_etl.extract scheduled__2024-11-21T00:00:00+00:00 [queued]>
[2024-11-22T06:39:04.382+0000] {taskinstance.py:2613} INFO - Dependencies all met for dep_context=requeueable deps ti=<TaskInstance: university_ranking_etl.extract scheduled__2024-11-21T00:00:00+00:00 [queued]>
[2024-11-22T06:39:04.436+0000] {taskinstance.py:2866} INFO - Starting attempt 2 of 2
[2024-11-22T06:39:04.714+0000] {taskinstance.py:2889} INFO - Executing <Task(PythonOperator): extract> on 2024-11-21 00:00:00+00:00
[2024-11-22T06:39:04.890+0000] {warnings.py:112} WARNING - /home/***/.local/lib/python3.12/site-packages/***/task/task_runner/standard_task_runner.py:70: DeprecationWarning: This process (pid=95) is multi-threaded, use of fork() may lead to deadlocks in the child.
  pid = os.fork()

[2024-11-22T06:39:04.902+0000] {standard_task_runner.py:104} INFO - Running: ['***', 'tasks', 'run', 'university_ranking_etl', 'extract', 'scheduled__2024-11-21T00:00:00+00:00', '--job-id', '74', '--raw', '--subdir', 'DAGS_FOLDER/etl_***.py', '--cfg-path', '/tmp/tmpmkl9iok5']
[2024-11-22T06:39:04.921+0000] {standard_task_runner.py:72} INFO - Started process 105 to run task
[2024-11-22T06:39:04.941+0000] {standard_task_runner.py:105} INFO - Job 74: Subtask extract
[2024-11-22T06:39:05.379+0000] {task_command.py:467} INFO - Running <TaskInstance: university_ranking_etl.extract scheduled__2024-11-21T00:00:00+00:00 [running]> on host e44b7385b491
[2024-11-22T06:39:07.702+0000] {taskinstance.py:3132} INFO - Exporting env vars: AIRFLOW_CTX_DAG_OWNER='***' AIRFLOW_CTX_DAG_ID='university_ranking_etl' AIRFLOW_CTX_TASK_ID='extract' AIRFLOW_CTX_EXECUTION_DATE='2024-11-21T00:00:00+00:00' AIRFLOW_CTX_TRY_NUMBER='2' AIRFLOW_CTX_DAG_RUN_ID='scheduled__2024-11-21T00:00:00+00:00'
[2024-11-22T06:39:07.721+0000] {logging_mixin.py:190} INFO - Task instance is in running state
[2024-11-22T06:39:07.737+0000] {logging_mixin.py:190} INFO -  Previous state of the Task instance: queued
[2024-11-22T06:39:07.744+0000] {logging_mixin.py:190} INFO - Current task name:extract state:running start_date:2024-11-22 06:39:04.278885+00:00
[2024-11-22T06:39:07.791+0000] {logging_mixin.py:190} INFO - Dag name:university_ranking_etl and current dag run status:running
[2024-11-22T06:39:07.821+0000] {taskinstance.py:731} INFO - ::endgroup::
[2024-11-22T06:39:07.830+0000] {logger.py:11} INFO - ====== WebDriver manager ======
[2024-11-22T06:39:07.988+0000] {logger.py:11} INFO - Get LATEST chromedriver version for google-chrome
[2024-11-22T06:39:14.198+0000] {logger.py:11} INFO - About to download new driver from https://chromedriver.storage.googleapis.com/114.0.5735.90/chromedriver_linux64.zip
[2024-11-22T06:39:14.486+0000] {logger.py:11} INFO - Driver downloading response is 200
[2024-11-22T06:39:20.473+0000] {logger.py:11} INFO - Get LATEST chromedriver version for google-chrome
[2024-11-22T06:39:21.513+0000] {logger.py:11} INFO - Get LATEST chromedriver version for google-chrome
[2024-11-22T06:39:21.865+0000] {logger.py:11} INFO - Driver has been saved in cache [/home/***/.wdm/drivers/chromedriver/linux64/114.0.5735.90]
[2024-11-22T06:39:21.949+0000] {taskinstance.py:3311} ERROR - Task failed with exception
Traceback (most recent call last):
  File "/home/airflow/.local/lib/python3.12/site-packages/airflow/models/taskinstance.py", line 767, in _execute_task
    result = _execute_callable(context=context, **execute_callable_kwargs)
             ^^^^^^^^^^^^^^^^^^^^^^^^^^^^^^^^^^^^^^^^^^^^^^^^^^^^^^^^^^^^^
  File "/home/airflow/.local/lib/python3.12/site-packages/airflow/models/taskinstance.py", line 733, in _execute_callable
    return ExecutionCallableRunner(
           ^^^^^^^^^^^^^^^^^^^^^^^^
  File "/home/airflow/.local/lib/python3.12/site-packages/airflow/utils/operator_helpers.py", line 252, in run
    return self.func(*args, **kwargs)
           ^^^^^^^^^^^^^^^^^^^^^^^^^^
  File "/home/airflow/.local/lib/python3.12/site-packages/airflow/models/baseoperator.py", line 417, in wrapper
    return func(self, *args, **kwargs)
           ^^^^^^^^^^^^^^^^^^^^^^^^^^^
  File "/home/airflow/.local/lib/python3.12/site-packages/airflow/operators/python.py", line 238, in execute
    return_value = self.execute_callable()
                   ^^^^^^^^^^^^^^^^^^^^^^^
  File "/home/airflow/.local/lib/python3.12/site-packages/airflow/operators/python.py", line 256, in execute_callable
    return runner.run(*self.op_args, **self.op_kwargs)
           ^^^^^^^^^^^^^^^^^^^^^^^^^^^^^^^^^^^^^^^^^^^
  File "/home/airflow/.local/lib/python3.12/site-packages/airflow/utils/operator_helpers.py", line 252, in run
    return self.func(*args, **kwargs)
           ^^^^^^^^^^^^^^^^^^^^^^^^^^
  File "/opt/airflow/dags/etl_airflow.py", line 18, in extract
    driver = webdriver.Chrome(service=Service(ChromeDriverManager().install()), options=options)
             ^^^^^^^^^^^^^^^^^^^^^^^^^^^^^^^^^^^^^^^^^^^^^^^^^^^^^^^^^^^^^^^^^^^^^^^^^^^^^^^^^^^
  File "/home/airflow/.local/lib/python3.12/site-packages/selenium/webdriver/chrome/webdriver.py", line 45, in __init__
    super().__init__(
  File "/home/airflow/.local/lib/python3.12/site-packages/selenium/webdriver/chromium/webdriver.py", line 55, in __init__
    self.service.start()
  File "/home/airflow/.local/lib/python3.12/site-packages/selenium/webdriver/common/service.py", line 102, in start
    self.assert_process_still_running()
  File "/home/airflow/.local/lib/python3.12/site-packages/selenium/webdriver/common/service.py", line 115, in assert_process_still_running
    raise WebDriverException(f"Service {self._path} unexpectedly exited. Status code was: {return_code}")
selenium.common.exceptions.WebDriverException: Message: Service /home/airflow/.wdm/drivers/chromedriver/linux64/114.0.5735.90/chromedriver unexpectedly exited. Status code was: 127

[2024-11-22T06:39:22.007+0000] {logging_mixin.py:190} INFO - Task instance in failure state
[2024-11-22T06:39:22.015+0000] {logging_mixin.py:190} INFO - Task start:2024-11-22 06:39:04.278885+00:00 end:2024-11-22 06:39:22.007138+00:00 duration:17.728253
[2024-11-22T06:39:22.018+0000] {logging_mixin.py:190} INFO - Task:<Task(PythonOperator): extract> dag:<DAG: university_ranking_etl> dagrun:<DagRun university_ranking_etl @ 2024-11-21 00:00:00+00:00: scheduled__2024-11-21T00:00:00+00:00, state:running, queued_at: 2024-11-22 06:22:36.236005+00:00. externally triggered: False>
[2024-11-22T06:39:22.023+0000] {logging_mixin.py:190} INFO - Failure caused by Message: Service /home/***/.wdm/drivers/chromedriver/linux64/114.0.5735.90/chromedriver unexpectedly exited. Status code was: 127
[2024-11-22T06:39:22.030+0000] {taskinstance.py:1225} INFO - Marking task as FAILED. dag_id=university_ranking_etl, task_id=extract, run_id=scheduled__2024-11-21T00:00:00+00:00, execution_date=20241121T000000, start_date=20241122T063904, end_date=20241122T063922
[2024-11-22T06:39:22.190+0000] {taskinstance.py:340} INFO - ::group::Post task execution logs
[2024-11-22T06:39:22.201+0000] {standard_task_runner.py:124} ERROR - Failed to execute job 74 for task extract (Message: Service /home/airflow/.wdm/drivers/chromedriver/linux64/114.0.5735.90/chromedriver unexpectedly exited. Status code was: 127
; 105)
Traceback (most recent call last):
  File "/home/airflow/.local/lib/python3.12/site-packages/airflow/task/task_runner/standard_task_runner.py", line 117, in _start_by_fork
    ret = args.func(args, dag=self.dag)
          ^^^^^^^^^^^^^^^^^^^^^^^^^^^^^
  File "/home/airflow/.local/lib/python3.12/site-packages/airflow/cli/cli_config.py", line 49, in command
    return func(*args, **kwargs)
           ^^^^^^^^^^^^^^^^^^^^^
  File "/home/airflow/.local/lib/python3.12/site-packages/airflow/utils/cli.py", line 116, in wrapper
    return f(*args, **kwargs)
           ^^^^^^^^^^^^^^^^^^
  File "/home/airflow/.local/lib/python3.12/site-packages/airflow/cli/commands/task_command.py", line 483, in task_run
    task_return_code = _run_task_by_selected_method(args, _dag, ti)
                       ^^^^^^^^^^^^^^^^^^^^^^^^^^^^^^^^^^^^^^^^^^^^
  File "/home/airflow/.local/lib/python3.12/site-packages/airflow/cli/commands/task_command.py", line 256, in _run_task_by_selected_method
    return _run_raw_task(args, ti)
           ^^^^^^^^^^^^^^^^^^^^^^^
  File "/home/airflow/.local/lib/python3.12/site-packages/airflow/cli/commands/task_command.py", line 341, in _run_raw_task
    return ti._run_raw_task(
           ^^^^^^^^^^^^^^^^^
  File "/home/airflow/.local/lib/python3.12/site-packages/airflow/utils/session.py", line 97, in wrapper
    return func(*args, session=session, **kwargs)
           ^^^^^^^^^^^^^^^^^^^^^^^^^^^^^^^^^^^^^^
  File "/home/airflow/.local/lib/python3.12/site-packages/airflow/models/taskinstance.py", line 3005, in _run_raw_task
    return _run_raw_task(
           ^^^^^^^^^^^^^^
  File "/home/airflow/.local/lib/python3.12/site-packages/airflow/models/taskinstance.py", line 273, in _run_raw_task
    TaskInstance._execute_task_with_callbacks(
  File "/home/airflow/.local/lib/python3.12/site-packages/airflow/models/taskinstance.py", line 3159, in _execute_task_with_callbacks
    result = self._execute_task(context, task_orig)
             ^^^^^^^^^^^^^^^^^^^^^^^^^^^^^^^^^^^^^^
  File "/home/airflow/.local/lib/python3.12/site-packages/airflow/models/taskinstance.py", line 3183, in _execute_task
    return _execute_task(self, context, task_orig)
           ^^^^^^^^^^^^^^^^^^^^^^^^^^^^^^^^^^^^^^^
  File "/home/airflow/.local/lib/python3.12/site-packages/airflow/models/taskinstance.py", line 767, in _execute_task
    result = _execute_callable(context=context, **execute_callable_kwargs)
             ^^^^^^^^^^^^^^^^^^^^^^^^^^^^^^^^^^^^^^^^^^^^^^^^^^^^^^^^^^^^^
  File "/home/airflow/.local/lib/python3.12/site-packages/airflow/models/taskinstance.py", line 733, in _execute_callable
    return ExecutionCallableRunner(
           ^^^^^^^^^^^^^^^^^^^^^^^^
  File "/home/airflow/.local/lib/python3.12/site-packages/airflow/utils/operator_helpers.py", line 252, in run
    return self.func(*args, **kwargs)
           ^^^^^^^^^^^^^^^^^^^^^^^^^^
  File "/home/airflow/.local/lib/python3.12/site-packages/airflow/models/baseoperator.py", line 417, in wrapper
    return func(self, *args, **kwargs)
           ^^^^^^^^^^^^^^^^^^^^^^^^^^^
  File "/home/airflow/.local/lib/python3.12/site-packages/airflow/operators/python.py", line 238, in execute
    return_value = self.execute_callable()
                   ^^^^^^^^^^^^^^^^^^^^^^^
  File "/home/airflow/.local/lib/python3.12/site-packages/airflow/operators/python.py", line 256, in execute_callable
    return runner.run(*self.op_args, **self.op_kwargs)
           ^^^^^^^^^^^^^^^^^^^^^^^^^^^^^^^^^^^^^^^^^^^
  File "/home/airflow/.local/lib/python3.12/site-packages/airflow/utils/operator_helpers.py", line 252, in run
    return self.func(*args, **kwargs)
           ^^^^^^^^^^^^^^^^^^^^^^^^^^
  File "/opt/airflow/dags/etl_airflow.py", line 18, in extract
    driver = webdriver.Chrome(service=Service(ChromeDriverManager().install()), options=options)
             ^^^^^^^^^^^^^^^^^^^^^^^^^^^^^^^^^^^^^^^^^^^^^^^^^^^^^^^^^^^^^^^^^^^^^^^^^^^^^^^^^^^
  File "/home/airflow/.local/lib/python3.12/site-packages/selenium/webdriver/chrome/webdriver.py", line 45, in __init__
    super().__init__(
  File "/home/airflow/.local/lib/python3.12/site-packages/selenium/webdriver/chromium/webdriver.py", line 55, in __init__
    self.service.start()
  File "/home/airflow/.local/lib/python3.12/site-packages/selenium/webdriver/common/service.py", line 102, in start
    self.assert_process_still_running()
  File "/home/airflow/.local/lib/python3.12/site-packages/selenium/webdriver/common/service.py", line 115, in assert_process_still_running
    raise WebDriverException(f"Service {self._path} unexpectedly exited. Status code was: {return_code}")
selenium.common.exceptions.WebDriverException: Message: Service /home/airflow/.wdm/drivers/chromedriver/linux64/114.0.5735.90/chromedriver unexpectedly exited. Status code was: 127

[2024-11-22T06:39:22.345+0000] {local_task_job_runner.py:266} INFO - Task exited with return code 1
[2024-11-22T06:39:23.340+0000] {taskinstance.py:3895} INFO - 0 downstream tasks scheduled from follow-on schedule check
[2024-11-22T06:39:23.413+0000] {local_task_job_runner.py:245} INFO - ::endgroup::
